{
  "timestamp": "2025-08-09T01:59:24.712976",
  "summary": {
    "total_services": 5,
    "healthy_services": 2,
    "success_rate": 0.4
  },
  "results": {
    "health_checks": {
      "agent-comms": {
        "status": "error",
        "error": "('Connection aborted.', ConnectionResetError(54, 'Connection reset by peer'))"
      },
      "task-generator": {
        "status": "healthy",
        "response": {
          "status": "healthy",
          "service": "task-generator",
          "results_consumer_running": true,
          "kafka_servers": "langgraph-system-kafka:9092",
          "input_topic": "dev-langgraph-agent-events",
          "results_topic": "dev-langgraph-task-results",
          "openai_configured": true,
          "task_results_count": 0
        }
      },
      "task-solver": {
        "status": "healthy",
        "response": {
          "status": "healthy",
          "service": "task-solver-agent",
          "consumer_running": true,
          "kafka_servers": "langgraph-system-kafka:9092",
          "input_topic": "dev-langgraph-agent-events",
          "output_topic": "dev-langgraph-task-results",
          "openai_configured": true,
          "processed_tasks_count": 0
        }
      }
    },
    "kafka": {
      "status": "error",
      "error": "KafkaTimeoutError: Failed to update metadata after 60.0 secs."
    },
    "agent_communication": {
      "status": "error",
      "error": "HTTPConnectionPool(host='localhost', port=8000): Max retries exceeded with url: /send_message (Caused by NewConnectionError('<urllib3.connection.HTTPConnection object at 0x1070bc710>: Failed to establish a new connection: [Errno 61] Connection refused'))"
    },
    "task_generator": {
      "status": "healthy",
      "response": {
        "status": "partial",
        "code": 404
      }
    },
    "task_solver": {
      "status": "healthy",
      "response": {
        "status": "partial",
        "code": 404
      }
    }
  }
}